Workbook

Sheet Staff Dashboard

Sheet Team Dashboard

Sheet Data
B2: All Sprint Details
B3: Sprint Name | C3: Check Now 26.17 | D3: Manual
B4: Date From | C4: 46047 | D4: Manual
B5: Date To | C5: 46058 | D5: Manual
B6: Product | C6: Check Now | D6: Manual
B7: Escaped Bugs | C7: 0 | D7: Manual
B8: MidSprint_Addition | C8: 2 | D8: All Team data with tag MidSprint_Addition
B9: Ad-hoc | C9: 10 | D9: All Team data with Ad-hoc
B10: Planned SP | C10: 57 | D10: Manual
B11: Actual SP | C11: 102 | D11: Manual
B12: Estimated Development Effort | C12: 569 | D12: Sum all work item type "Original Estimate" in the activity development, frontend, and design from All Sprint data
B13: Total Actual Development Effort | C13: 776.46 | D13: Sum all work item type "Completed Work "in the activity development, frontend, and design from All Sprint data
B14: Estimated Testing Effort | C14: 97 | D14: Sum all work item type"Original Estimate" in the activity Testing from All Sprint data
B15: Total Actual Testing Effort | C15: 99.5 | D15: Sum all work item type "Original Estimate" in the activity Testing from All Sprint data
B16: Bug Fixing Actual Effort | C16: 2 | D16: Sum all work item type "Completed Work " with tag "Bug Fixing Actual Effort"
B17: Sum of Actual Hours | C17: 875.96 | D17: Sum all work item typeCompleted Work " in the activity all
B18: Sum of Working Hours | C18: 680 | D18: Sum Remaining Capacity from Team Capacity
B20: All Sprint Data | U20: Team Capacity
B21: EPIC | C21: Parent | D21: Work Item Type | E21: Title | F21: Story Points | G21: State | H21: Assigned To | I21: Original Estimate | J21: Completed Work | K21: Remaining Work | L21: Priority | M21: Severity | N21: Phase | O21: Dev delivery date | P21: QC Delivery date | Q21: Tags | R21: Task Category | S21: Activity | U21: Team member | V21: Team | W21: Total Expected Working Hours per Sprint | X21: Total official vacation | Y21: Total personal Days Off | Z21: Remaining Capacity | AB21: Team | AC21: Now
C22: 260177 | D22: Task | E22: Breadcrumb inputs/outputs | G22: Done | H22: Enas Diab <ediab@youxel.com> | I22: 3 | J22: 6 | K22: 0 | L22: 2 | R22: Development | S22: Front End | U22: Ahmed Talaat <atalaat@youxel.com> | V22: Development | W22: =7*10 -> 70 | X22: 0 | Y22: 1 | Z22: =7*9 -> 63 | AB22: Design | AC22: =SUMIF(V22:V32,V31,Z22:Z32) -> 203
C23: 260177 | D23: Task | E23: BreadCrumb-menu | G23: Done | H23: Enas Diab <ediab@youxel.com> | I23: 5 | J23: 4 | K23: 1 | L23: 2 | R23: Development | S23: Front End | U23: Alaa Ezzat <aezzat@youxel.com> | V23: Frontend | W23: =7*10 -> 70 | X23: 0 | Y23: 1 | Z23: =7*9 -> 63 | AB23: Development | AC23: =SUMIF(V22:V32,V27,Z22:Z32) -> 189
C24: 251892 | D24: Task | E24: Create Lottie Component Structure & inputs | G24: Done | H24: Hussein Abdallah <habdallah@youxel.com> | I24: 2 | J24: 2 | K24: 0 | L24: 2 | Q24: MidSprint_Addition | R24: Development | S24: Front End | U24: Enas Diab <ediab@youxel.com> | V24: Frontend | W24: =4*10 -> 40 | X24: 0 | Y24: 1 | Z24: =4*9 -> 36 | AB24: Front End | AC24: =SUMIF(V22:V32,V26,Z22:Z32) -> 218
C25: 251892 | D25: Task | E25: UI: Lottie Color | G25: Done | H25: Shimaa Mohamed Elsayed <shhadad@youxel.com> | I25: 4 | J25: 13.67 | K25: 0 | L25: 2 | R25: Design | S25: Design | U25: Galal Torkey <gtorkey@youxel.com> | V25: Testing | W25: =7*10 -> 70 | X25: 0 | Y25: 0 | Z25: =7*10 -> 70 | AB25: Testing | AC25: =SUMIF(V22:V32,V25,Z22:Z32) -> 70
C26: 233816 | D26: Task | E26: UI:: Toggle Button | G26: Done | H26: Shimaa Mohamed Elsayed <shhadad@youxel.com> | I26: 4 | J26: 2.5 | K26: 0 | L26: 2 | R26: Design | S26: Design | U26: Hussein Abdallah <habdallah@youxel.com> | V26: Frontend | W26: =7*10 -> 70 | X26: 0 | Y26: 0 | Z26: =7*10 -> 70 | AB26: IOS Dev | AC26: =SUMIF(V22:V32,#REF!,Z22:Z32) -> 0
C27: 233934 | D27: Task | E27: FE :: Edit in galleria component in UI kit | G27: Done | H27: Hussein Abdallah <habdallah@youxel.com> | I27: 3 | J27: 3 | K27: 0 | L27: 2 | R27: Development | S27: Front End | U27: Mahmoud Adel Ali <madeel@youxel.com> | V27: Development | W27: =7*10 -> 70 | X27: 0 | Y27: 2 | Z27: =7*8 -> 56 | AB27: Andriod Dev | AC27: =SUMIF(V22:V32,#REF!,Z22:Z32) -> 0
C28: 255495 | D28: Task | E28: FE:: Add action menu column to table | G28: Done | H28: Hussein Abdallah <habdallah@youxel.com> | I28: 4 | J28: 4 | K28: 0 | L28: 2 | R28: Development | S28: Front End | U28: Mahmoud Ibrahim Elfeqy <mfeqy@youxel.com> | V28: Development | W28: =7*10 -> 70 | X28: 0 | Y28: 0 | Z28: =7*10 -> 70 | AB28: Total | AC28: =SUM(AC22:AC27) -> 680
C29: 255495 | D29: Task | E29: Design :: Unify status and tag components | G29: Active | H29: Mariam Mohamed Saeed <msaeed@youxel.com> | I29: 5 | J29: 4.4 | K29: 0.6 | L29: 2 | R29: Design | S29: Design | U29: Mariam Mohamed Saeed <msaeed@youxel.com> | V29: Design | W29: =7*10 -> 70 | X29: 0 | Y29: 0 | Z29: =7*10 -> 70
C30: 250832 | D30: Task | E30: UI:: Contextual Button Component | G30: Ready For Review | H30: Shimaa Mohamed Elsayed <shhadad@youxel.com> | I30: 5 | J30: 5 | K30: 0 | L30: 2 | R30: Design | S30: Design | U30: Mohamed Mustafa Farrag <mfarrag@youxel.com> | V30: Frontend | W30: =7*10 -> 70 | X30: 0 | Y30: 3 | Z30: =7*7 -> 49
C31: 250832 | D31: Task | E31: Design system: date and time documentation | G31: Done | H31: Mariam Mohamed Saeed <msaeed@youxel.com> | I31: 3 | J31: 7.67 | K31: 0 | L31: 2 | R31: Design | S31: Design | U31: Salma Sameh <ssameh@youxel.com> | V31: Design | W31: =7*10 -> 70 | X31: 0 | Y31: 0 | Z31: =7*10 -> 70
C32: 250832 | D32: Task | E32: design systems: create date and time component | G32: Done | H32: Mariam Mohamed Saeed <msaeed@youxel.com> | I32: 5 | J32: 16.34 | K32: 0 | L32: 2 | R32: Design | S32: Design | U32: Shimaa Mohamed Elsayed <shhadad@youxel.com> | V32: Design | W32: =7*10 -> 70 | X32: 0 | Y32: 1 | Z32: =7*9 -> 63
C33: 250832 | D33: Task | E33: UI:: DropDown/Checkboxes/Radio:: Add other option & Input | G33: Done | H33: Mariam Mohamed Saeed <msaeed@youxel.com> | I33: 3 | J33: 3.5 | K33: 0 | L33: 2 | R33: Design | S33: Design | U33: Total | Z33: =SUM(Z22:Z32) -> 680
C34: 250832 | D34: Task | E34: Design system: typography | G34: Done | H34: Mariam Mohamed Saeed <msaeed@youxel.com> | I34: 2 | J34: 14.5 | K34: 0 | L34: 2 | R34: Design | S34: Design
C35: 250832 | D35: Task | E35: UI:: Text Area:: Rich text editor | G35: Done | H35: Mariam Mohamed Saeed <msaeed@youxel.com> | I35: 3 | J35: 3.92 | K35: 0 | L35: 2 | R35: Design | S35: Design
C36: 250832 | D36: Task | E36: Design system: Side Menu Documentation and add new variants | G36: Done | H36: Mariam Mohamed Saeed <msaeed@youxel.com> | I36: 6 | J36: 7.07 | K36: 0 | L36: 2 | R36: Design | S36: Design
C37: 250832 | D37: Task | E37: UI:: Tree Select:: Documentation | G37: Done | H37: Mariam Mohamed Saeed <msaeed@youxel.com> | I37: 4 | J37: 6 | K37: 0 | L37: 2 | R37: Documentation | S37: Design
C38: 250832 | D38: Task | E38: UI:: Tree Select:: Build Component | G38: Done | H38: Mariam Mohamed Saeed <msaeed@youxel.com> | I38: 5 | J38: 10.5 | K38: 0 | L38: 2 | R38: Design | S38: Design
C39: 250832 | D39: Task | E39: UI:: Split button- Documentation | G39: Done | H39: Mariam Mohamed Saeed <msaeed@youxel.com> | I39: 3 | J39: 4.5 | K39: 0 | L39: 2 | R39: Documentation | S39: Design
C40: 250832 | D40: Task | E40: UI:: Split button- Create Components | G40: Ready For Review | H40: Mariam Mohamed Saeed <msaeed@youxel.com> | I40: 7 | J40: 17 | K40: 0 | L40: 2 | R40: Design | S40: Design
C41: 250832 | D41: Task | E41: UX:: Documentation Tabs / Tab Category | G41: Done | H41: Mariam Mohamed Saeed <msaeed@youxel.com> | I41: 4 | J41: 2 | K41: 2 | L41: 2 | R41: Documentation | S41: Design
C42: 250832 | D42: Task | E42: UI:: Tabs Variants>> Survey | G42: Done | H42: Mariam Mohamed Saeed <msaeed@youxel.com> | I42: 3 | J42: 1.5 | K42: 1.5 | L42: 2 | R42: Design | S42: Design
...

Sheet Analysis
B2: CMMI Measures
B3: Measure | C3: Description | D3: Calculation | E3: Frequency | F3: Analysis
B4: Completion rate | C4: Measures the difference between the actual done story points VS. the Planned story points | D4: Actual SP / Planned SP | E4: Sprint | F4: +90%
B5: Effort estimation accuracy percentage | C5: Total Planned Development hours / Total Actual Development Hours | D5: Sum Total Planned hours/Total Actual Dev. Effort) | E5: Sprint | F5: 90% - till 120%
B6: Project Rework Rate | C6: Project Calculate man hours used in fixing the bugs returned from testing compared to the total actual dev. hours. | D6: Bug Fixing Actual Effort /Total Actual Dev. Effort) *100 | E6: Sprint | F6: 0% – 10%
B7: Escaped Bugs | C7: defects that bypass one or more testing or quality assurance stages and are later post released | D7: Number of bypass one or more testing or quality assurance stages | E7: Sprint / release | F7: 2% -15%
B8: Utilization | C8: This measure is related to the Actual effort VS. working hours | D8: (Sum of Actual hours / Sum working hours) *100 | E8: Sprint | F8: (90%-100%
B9: Effort Variance | C9: Calculate the variance of the estimated dev. Hours compared to the total actual dev. hours. | D9: ((Total Actual Dev. Effort - Estimated Dev. Effort)/ Estimated Dev. Effort )*100 | E9: Sprint | F9: 5 – 10%
B11: Measure | C11: Description | D11: Formula | E11: Value | F11: Target Range | G11: Status
B12: Completion Rate | C12: Measures the difference between the actual done story points vs. the planned story points | F12: ≥ 90%
B13: Effort Estimation Accuracy % (Dev) | C13: Planned development hours vs. actual development hours | F13: 90% – 120%
B14: Project Rework Rate | C14: Bug fixing effort compared to total actual development effort | F14: 0% – 10%
B15: Escaped Bugs | C15: Defects found after release | F15: 2% – 15%
B16: Utilization | C16: Actual effort vs. available working hours | F16: 90% – 100%
B17: Effort Variance (Dev) | C17: Variance between estimated and actual development effort | F17: 5% – 10%
B19: Row Labels | C19: Sum of Original Estimate | D19: Sum of Completed Work | E19: Sum of Remaining Work
B20: Ahmed Talaat <atalaat@youxel.com> | C20: 26 | D20: 63 | E20: 10 | F20: from data table per name
B21: Alaa Ezzat <aezzat@youxel.com> | C21: 56.5 | D21: 90 | E21: 9
B22: Enas Diab <ediab@youxel.com> | C22: 12 | D22: 14 | E22: 1
B23: Galal Torkey <gtorkey@youxel.com> | C23: 97 | D23: 99.5 | E23: 7
B24: Hussein Abdallah <habdallah@youxel.com> | C24: 48 | D24: 77 | E24: 0.5
B25: Mahmoud Adel Ali <madeel@youxel.com> | C25: 94 | D25: 104 | E25: 0
B26: Mahmoud Ibrahim Elfeqy <mfeqy@youxel.com> | C26: 64 | D26: 85 | E26: 0
B27: Mariam Mohamed Saeed <msaeed@youxel.com> | C27: 64 | D27: 111.83 | E27: 9.25
B28: Mohamed Mustafa Farrag <mfarrag@youxel.com> | C28: 49 | D28: 31 | E28: 18.5
B29: Salma Sameh <ssameh@youxel.com> | C29: 89 | D29: 109.92 | E29: 6.5
B30: Shimaa Mohamed Elsayed <shhadad@youxel.com> | C30: 66.5 | D30: 90.71 | E30: 3.75
B31: Grand Total | C31: =SUM(C20:C30) -> 666 | D31: =SUM(D20:D30) -> 875.96 | E31: =SUM(E20:E30) -> 65.5

Sheet Kpi Indicators Per Staff
B2: Kpi Indicators Per Staff
B3: Team Member | C3: Check Now 25.9 | D3: Check Now 25.10 | E3: Check Now 25.11 | F3: Check Now 25.12 | G3: Check Now 25.13 | H3: Check Now 25.14 | I3: Check Now 26.15 | J3: Check Now 26.16 | K3: Check Now 26.17
B4: Ahmed Talaat <atalaat@youxel.com> | C4: 0.46085714 | D4: 1.0578923 | E4: 0.98841379 | F4: 1.0757576 | G4: 1.0725 | H4: 0.6537064 | I4: 0.94960317 | J4: 1.0228571 | K4: ='Kpi Indicators'!I3 -> 0.87123288
B5: Alaa Ezzat <aezzat@youxel.com> | C5: 0.3491166 | D5: 0.9961039 | E5: 0.8232996 | F5: 0.97324042 | G5: 0.94160998 | H5: 0.84953819 | I5: 0.93149541 | J5: 0.70691268 | K5: ='Kpi Indicators'!I4 -> 0.81699856
B6: Enas Diab <ediab@youxel.com> | C6: 0.68257407 | D6: 0.63793561 | E6: 0.76103296 | F6: 0.91940334 | G6: 0.89002193 | H6: 0.90059889 | I6: 0.89747475 | J6: 0.62873134 | K6: ='Kpi Indicators'!I5 -> 0.89888889
B7: Galal Torkey <gtorkey@youxel.com> | C7: NA | D7: NA | E7: NA | F7: NA | G7: NA | H7: 0.88979048 | I7: 0.97796992 | J7: 0.89605321 | K7: ='Kpi Indicators'!I6 -> 1.0009691
B8: Hussein Abdallah <habdallah@youxel.com> | C8: 0.54751014 | D8: 0.73974359 | E8: 0.71913439 | F8: 0.7976 | G8: 0.74878228 | H8: 0.82031746 | I8: 0.96374175 | J8: 0.94367063 | K8: ='Kpi Indicators'!I7 -> 0.93387097
B9: Mahmoud Adel Ali <madeel@youxel.com> | C9: 0.91147049 | D9: 0.5826416 | E9: 1.043703 | F9: 1.0634054 | G9: 1.0433862 | H9: 1.0234252 | I9: 1.0468944 | J9: 0.98509007 | K9: ='Kpi Indicators'!I8 -> 1.0664835
B10: Mahmoud Ibrahim Elfeqy <mfeqy@youxel.com> | C10: 0.57038086 | D10: 0.99154351 | E10: 0.942442 | F10: 1.002381 | G10: 1.1216667 | H10: 0.96282609 | I10: 0.95533769 | J10: 0.97772397 | K10: ='Kpi Indicators'!I9 -> 0.97201681
B11: Mariam Mohamed Saeed <msaeed@youxel.com> | C11: NA | D11: NA | E11: NA | F11: NA | G11: NA | H11: NA | I11: NA | J11: 0.69060012 | K11: ='Kpi Indicators'!I10 -> 0.81810395
B12: Mohamed Mustafa Farrag <mfarrag@youxel.com> | C12: 0.35228571 | D12: 0.86299955 | E12: 0.47142857 | F12: 0.54825397 | G12: 0.7552381 | H12: 0.8473514 | I12: 0.8789441 | J12: 0.70952381 | K12: ='Kpi Indicators'!I11 -> 0.7112451
B13: Salma Sameh <ssameh@youxel.com> | C13: 0.32551353 | D13: 0.55674812 | E13: 0.66460126 | F13: 0.53895105 | G13: 0.64520467 | H13: 0.52532309 | I13: 0.67323167 | J13: 0.76734658 | K13: ='Kpi Indicators'!I12 -> 1.0099233
B14: Shimaa Mohamed Elsayed <shhadad@youxel.com> | C14: 0.4912729 | D14: 1.1688824 | E14: 0.82427066 | F14: 0.6874965 | G14: 0.67466883 | H14: 0.63557056 | I14: 0.89049884 | J14: 0.89016726 | K14: ='Kpi Indicators'!I13 -> 0.98478447
B16: Performance Rate Per Staff | M16: Utilization Per Staff
B17: Team Member | C17: Check Now 25.9 | D17: Check Now 25.10 | E17: Check Now 25.11 | F17: Check Now 25.11 | G17: Check Now 25.13 | H17: Check Now 25.14 | I17: Check Now 26.15 | J17: Check Now 26.16 | K17: Check Now 26.17 | M17: Team Member | N17: Check Now 25.9 | O17: Check Now 25.10 | P17: Check Now 25.11 | Q17: Check Now 25.12 | R17: Check Now 25.13 | S17: Check Now 25.14 | T17: Check Now 26.15 | U17: Check Now 26.16 | V17: Check Now 26.17
B18: Ahmed Talaat <atalaat@youxel.com> | C18: 0.79 | D18: 0.91803279 | E18: 0.86206897 | F18: 0.87878788 | G18: 0.675 | H18: 0.29457364 | I18: 0.76190476 | J18: 1 | K18: ='Check Now 26.17 Full Analysis'!C6 -> 0.35616438 | M18: Ahmed Talaat <atalaat@youxel.com> | N18: 1.0285714 | O18: 1.7428571 | P18: 1.16 | Q18: 2 | R18: 2.375 | S18: 1.28125 | T18: 0.97222222 | U18: 1.2285714 | V18: ='Check Now 26.17 Full Analysis'!D6 -> 1
B19: Alaa Ezzat <aezzat@youxel.com> | C19: 0.743083 | D19: 0.90909091 | E19: 0.96842105 | F19: 0.7804878 | G19: 0.63265306 | H19: 0.7815534 | I19: 0.73684211 | J19: 0.48648649 | K19: ='Check Now 26.17 Full Analysis'!C7 -> 0.57070707 | M19: Alaa Ezzat <aezzat@youxel.com> | N19: 0.605 | O19: 1.1428571 | P19: 1.45 | Q19: 1.1714286 | R19: 1.1507937 | S19: 1.2285714 | T19: 0.84126984 | U19: 1.25 | V19: ='Check Now 26.17 Full Analysis'!D7 -> 1.4285714
B20: Enas Diab <ediab@youxel.com> | C20: 0.97468354 | D20: 0.6969697 | E20: 0.55434783 | F20: 0.54651163 | G20: 0.54385965 | H20: 0.60810811 | I20: 0.5 | J20: 0.26865672 | K20: ='Check Now 26.17 Full Analysis'!C8 -> 0.8 | M20: Enas Diab <ediab@youxel.com> | N20: 1.1071429 | O20: 1.71875 | P20: 1.9722222 | Q20: 2.0555556 | R20: 1.6875 | S20: 2.0625 | T20: 1.6111111 | U20: 1.75 | V20: ='Check Now 26.17 Full Analysis'!D8 -> 0.38888889
B21: Galal Torkey <gtorkey@youxel.com> | C21: NA | D21: NA | E21: NA | F21: NA | G21: NA | H21: 0.768 | I21: 0.86842105 | J21: 0.84393064 | K21: ='Check Now 26.17 Full Analysis'!C9 -> 0.91079812 | M21: Galal Torkey <gtorkey@youxel.com> | N21: NA | O21: NA | P21: NA | Q21: NA | R21: NA | S21: 0.82857143 | T21: 1.0428571 | U21: 1.1857143 | V21: ='Check Now 26.17 Full Analysis'!D9 -> 1.4214286
B22: Hussein Abdallah <habdallah@youxel.com> | C22: 0.71532847 | D22: 0.61538462 | E22: 0.84462151 | F22: 0.848 | G22: 0.61052632 | H22: 0.82777778 | I22: 0.61235955 | J22: 0.76388889 | K22: ='Check Now 26.17 Full Analysis'!C10 -> 0.61935484 | M22: Hussein Abdallah <habdallah@youxel.com> | N22: 0.77777778 | O22: 1.5 | P22: 1.1785714 | Q22: 1.73 | R22: 1.0928571 | S22: 1.047619 | T22: 1.4126984 | U22: 1.2589286 | V22: ='Check Now 26.17 Full Analysis'!D10 -> 1.1
B23: Mahmoud Adel Ali <madeel@youxel.com> | C23: 0.94366197 | D23: 0.94382022 | E23: 0.93835616 | F23: 1.1830986 | G23: 1.0740741 | H23: 0.86315789 | I23: 0.91304348 | J23: 0.71910112 | K23: ='Check Now 26.17 Full Analysis'!C11 -> 0.90384615 | M23: Mahmoud Adel Ali <madeel@youxel.com> | N23: 1.1607143 | O23: 0.93877551 | P23: 1.7936508 | Q23: 1.2678571 | R23: 1.2857143 | S23: 1.5079365 | T23: 1.6428571 | U23: 1.4126984 | V23: ='Check Now 26.17 Full Analysis'!D11 -> 1.8571429
B24: Mahmoud Ibrahim Elfeqy <mfeqy@youxel.com> | C24: 0.7752809 | D24: 0.85057471 | E24: 0.81538462 | F24: 0.8452381 | G24: 0.775 | H24: 0.73913043 | I24: 0.64705882 | J24: 0.74576271 | K24: ='Check Now 26.17 Full Analysis'!C12 -> 0.75294118 | M24: Mahmoud Ibrahim Elfeqy <mfeqy@youxel.com> | N24: 0.97142857 | O24: 1.2142857 | P24: 1.5714286 | Q24: 1.3333333 | R24: 2.6666667 | S24: 1.15 | T24: 1.2592593 | U24: 1.2857143 | V24: ='Check Now 26.17 Full Analysis'!D12 -> 1.2142857
B25: Mariam Mohamed Saeed <msaeed@youxel.com> | C25: NA | D25: NA | E25: NA | F25: NA | G25: NA | H25: NA | I25: NA | J25: 0.73115186 | K25: ='Check Now 26.17 Full Analysis'!C13 -> 0.52857615 | M25: Mariam Mohamed Saeed <msaeed@youxel.com> | N25: NA | O25: NA | P25: NA | Q25: NA | R25: NA | S25: NA | T25: NA | U25: 0.91428571 | V25: ='Check Now 26.17 Full Analysis'!D13 -> 1.5975714
B26: Mohamed Mustafa Farrag <mfarrag@youxel.com> | C26: 0.84 | D26: 0.96261682 | E26: 0.8 | F26: 1 | G26: 1 | H26: 0.99300699 | I26: 0.63043478 | J26: 1 | K26: ='Check Now 26.17 Full Analysis'!C14 -> 0.98989899 | M26: Mohamed Mustafa Farrag <mfarrag@youxel.com> | N26: 0.44285714 | O26: 0.87142857 | P26: 0.31428571 | Q26: 0.37142857 | R26: 0.88571429 | S26: 0.8 | T26: 0.52857143 | U26: 0.42857143 | V26: ='Check Now 26.17 Full Analysis'!D14 -> 0.63265306
B27: Salma Sameh <ssameh@youxel.com> | C27: 0.82921051 | D27: 0.94191523 | E27: 0.65826727 | F27: 0.72977904 | G27: 0.75453524 | H27: 0.81357975 | I27: 0.88282504 | J27: 0.83239955 | K27: ='Check Now 26.17 Full Analysis'!C15 -> 0.76447346 | M27: Salma Sameh <ssameh@youxel.com> | N27: 1.0967143 | O27: 1.2336508 | P27: 1.0217857 | Q27: 1.0132857 | R27: 0.85964286 | S27: 1.0010714 | T27: 0.76666667 | U27: 1.342 | V27: ='Check Now 26.17 Full Analysis'!D15 -> 1.5702857
B28: Shimaa Mohamed Elsayed <shhadad@youxel.com> | C28: 0.75806452 | D28: 0.8627451 | E28: 0.89994706 | F28: 0.82 | G28: 0.70857143 | H28: 0.88329261 | I28: 0.52017937 | J28: 0.6955506 | K28: ='Check Now 26.17 Full Analysis'!C16 -> 0.70400169 | M28: Shimaa Mohamed Elsayed <shhadad@youxel.com> | N28: 0.7716 | O28: 5.7633333 | P28: 1.1928125 | Q28: 0.92727273 | R28: 0.95454545 | S28: 1.21875 | T28: 0.86462963 | U28: 1.0705714 | V28: ='Check Now 26.17 Full Analysis'!D16 -> 1.4398413
B30: Done Tasks Per Staff | M30: MidSprint_Addition Per Staff
B31: Team Member | C31: Check Now 25.9 | D31: Check Now 25.10 | E31: Check Now 25.11 | F31: Check Now 25.11 | G31: Check Now 25.13 | H31: Check Now 25.14 | I31: Check Now 26.15 | J31: Check Now 26.16 | K31: Check Now 26.17 | M31: Team Member | N31: Check Now 25.9 | O31: Check Now 25.10 | P31: Check Now 25.11 | Q31: Check Now 25.12 | R31: Check Now 25.13 | S31: Check Now 25.14 | T31: Check Now 26.15 | U31: Check Now 26.16 | V31: Check Now 26.17
B32: Ahmed Talaat <atalaat@youxel.com> | C32: 0.28571429 | D32: 1 | E32: 1 | F32: 1 | G32: 1 | H32: 0.66666667 | I32: 1 | J32: 1 | K32: ='Check Now 26.17 Full Analysis'!D20 -> 1 | M32: Ahmed Talaat <atalaat@youxel.com> | N32: 0 | O32: 0 | P32: 0 | Q32: 0 | R32: 0 | S32: 0 | T32: 0 | U32: 0 | V32: ='Check Now 26.17 Full Analysis'!D34 -> 0
B33: Alaa Ezzat <aezzat@youxel.com> | C33: 0.2 | D33: 1 | E33: 0.69230769 | F33: 1 | G33: 1 | H33: 0.81481481 | I33: 1 | J33: 0.69230769 | K33: ='Check Now 26.17 Full Analysis'!D21 -> 0.8 | M33: Alaa Ezzat <aezzat@youxel.com> | N33: 0 | O33: 0 | P33: 0.19230769 | Q33: 0.875 | R33: 0.125 | S33: 0.074074074 | T33: 0.21052632 | U33: 0.076923077 | V33: ='Check Now 26.17 Full Analysis'!D35 -> 0
B34: Enas Diab <ediab@youxel.com> | C34: 0.53846154 | D34: 0.46666667 | E34: 0.64705882 | F34: 0.86363636 | G34: 0.875 | H34: 0.81818182 | I34: 0.90909091 | J34: 0.57142857 | K34: ='Check Now 26.17 Full Analysis'!D22 -> 1 | M34: Enas Diab <ediab@youxel.com> | N34: 0 | O34: 0.4 | P34: 0.058823529 | Q34: 0.13636364 | R34: 0 | S34: 0 | T34: 0 | U34: 0.28571429 | V34: ='Check Now 26.17 Full Analysis'!D36 -> 0
B35: Galal Torkey <gtorkey@youxel.com> | C35: NA | D35: NA | E35: NA | F35: NA | G35: NA | H35: 0.93333333 | I35: 1 | J35: 0.86956522 | K35: ='Check Now 26.17 Full Analysis'!D23 -> 0.96666667 | M35: Galal Torkey <gtorkey@youxel.com> | N35: NA | O35: NA | P35: NA | Q35: NA | R35: NA | S35: 0 | T35: 0 | U35: 0 | V35: ='Check Now 26.17 Full Analysis'!D37 -> 0
B36: Hussein Abdallah <habdallah@youxel.com> | C36: 0.46666667 | D36: 0.66666667 | E36: 0.61764706 | F36: 0.65 | G36: 0.73913043 | H36: 0.78571429 | I36: 1 | J36: 0.95 | K36: ='Check Now 26.17 Full Analysis'!D24 -> 1 | M36: Hussein Abdallah <habdallah@youxel.com> | N36: 0 | O36: 0 | P36: 0.029411765 | Q36: 0.05 | R36: 0.2173913 | S36: 0 | T36: 0 | U36: 0 | V36: ='Check Now 26.17 Full Analysis'!D38 -> 0.071428571
B37: Mahmoud Adel Ali <madeel@youxel.com> | C37: 0.86666667 | D37: 0.42857143 | E37: 0.96666667 | F37: 1 | G37: 1 | H37: 1 | I37: 1 | J37: 1 | K37: ='Check Now 26.17 Full Analysis'!D25 -> 1 | M37: Mahmoud Adel Ali <madeel@youxel.com> | N37: 0.066666667 | O37: 0.14285714 | P37: 0 | Q37: 0 | R37: 0 | S37: 0 | T37: 0 | U37: 0 | V37: ='Check Now 26.17 Full Analysis'!D39 -> 0
B38: Mahmoud Ibrahim Elfeqy <mfeqy@youxel.com> | C38: 0.45454545 | D38: 1 | E38: 0.88888889 | F38: 1 | G38: 1 | H38: 1 | I38: 1 | J38: 1 | K38: ='Check Now 26.17 Full Analysis'!D26 -> 1 | M38: Mahmoud Ibrahim Elfeqy <mfeqy@youxel.com> | N38: 0.090909091 | O38: 0 | P38: 0 | Q38: 0 | R38: 0 | S38: 0.083333333 | T38: 0 | U38: 0 | V38: ='Check Now 26.17 Full Analysis'!D40 -> 0
B39: Mariam Mohamed Saeed <msaeed@youxel.com> | C39: NA | D39: NA | E39: NA | F39: NA | G39: NA | H39: NA | I39: NA | J39: 0.64705882 | K39: ='Check Now 26.17 Full Analysis'!D27 -> 0.78947368 | M39: Mariam Mohamed Saeed <msaeed@youxel.com> | N39: NA | O39: NA | P39: NA | Q39: NA | R39: NA | S39: NA | T39: NA | U39: 0 | V39: ='Check Now 26.17 Full Analysis'!D41 -> 0
B40: Mohamed Mustafa Farrag <mfarrag@youxel.com> | C40: 0.2 | D40: 0.83333333 | E40: 0.4 | F40: 0.44444444 | G40: 0.66666667 | H40: 0.8125 | I40: 1 | J40: 0.66666667 | K40: ='Check Now 26.17 Full Analysis'!D28 -> 0.64285714 | M40: Mohamed Mustafa Farrag <mfarrag@youxel.com> | N40: 0 | O40: 0.083333333 | P40: 0 | Q40: 0 | R40: 0 | S40: 0.375 | T40: 0 | U40: 0 | V40: ='Check Now 26.17 Full Analysis'!D42 -> 0
B41: Salma Sameh <ssameh@youxel.com> | C41: 0.071428571 | D41: 0.35 | E41: 0.61538462 | F41: 0.41666667 | G41: 0.58333333 | H41: 0.375 | I41: 0.6 | J41: 0.66666667 | K41: ='Check Now 26.17 Full Analysis'!D29 -> 1 | M41: Salma Sameh <ssameh@youxel.com> | N41: 0 | O41: 0.35 | P41: 0.30769231 | Q41: 0.25 | R41: 0 | S41: 0.0625 | T41: 0 | U41: 0 | V41: ='Check Now 26.17 Full Analysis'!D43 -> 0
B42: Shimaa Mohamed Elsayed <shhadad@youxel.com> | C42: 0.375 | D42: 0.6 | E42: 0.75 | F42: 0.61538462 | G42: 0.625 | H42: 0.48148148 | I42: 1 | J42: 0.92 | K42: ='Check Now 26.17 Full Analysis'!D30 -> 1 | M42: Shimaa Mohamed Elsayed <shhadad@youxel.com> | N42: 0 | O42: 0 | P42: 0 | Q42: 0.076923077 | R42: 0.375 | S42: 0.2962963 | T42: 0.11111111 | U42: 0 | V42: ='Check Now 26.17 Full Analysis'!D44 -> 0.041666667
M44: Ad-hoc % Per Staff
...

Sheet Kpi Indicators Per Team
B2: Item | C2: Check Now 25.9 | D2: Check Now 25.10 | E2: Check Now 25.11 | F2: Check Now 25.12 | G2: Check Now 25.13 | H2: Check Now 25.14 | I2: Check Now 26.15 | J2: Check Now 26.16 | K2: Check Now 26.17
B3: Escaped Bugs | C3: 0 | D3: 0 | E3: 0 | F3: 0 | G3: 0 | H3: 0 | I3: 0 | J3: 0 | K3: ='Check Now 26.17 Analysis'!C6 -> 0
B4: MidSprint_Addition | C4: 2 | D4: 23 | E4: 14 | F4: 18 | G4: 10 | H4: 25 | I4: 8 | J4: 11 | K4: ='Check Now 26.17 Analysis'!C7 -> 2
B5: Ad-hoc | C5: NA | D5: NA | E5: NA | F5: NA | G5: NA | H5: NA | I5: 9 | J5: 12 | K5: ='Check Now 26.17 Analysis'!C8 -> 10
B6: Actual SP | C6: 31 | D6: 31 | E6: 66 | F6: 72 | G6: 78 | H6: 57 | I6: 73 | J6: 61 | K6: ='Check Now 26.17 Analysis'!C9 -> 57
B7: Planned SP | C7: 87 | D7: 97 | E7: 113 | F7: 124 | G7: 142 | H7: 191 | I7: 82 | J7: 44 | K7: ='Check Now 26.17 Analysis'!C10 -> 102
B8: Estimated Development Effort | C8: 721.5 | D8: 716 | E8: 775.5 | F8: 578 | G8: 436.5 | H8: 694.5 | I8: 476 | J8: 639.5 | K8: ='Check Now 26.17 Analysis'!C11 -> 569
B9: Total Actual Development Effort | C9: 562.13 | D9: 599.79 | E9: 667.21 | F9: 596.76 | G9: 547.89 | H9: 699.58 | I9: 619.26 | J9: 757.18 | K9: ='Check Now 26.17 Analysis'!C12 -> 776.46
B10: Estimated Testing Effort | C10: 0 | D10: 0 | E10: 0 | F10: 0 | G10: 0 | H10: 48 | I10: 66 | J10: 73 | K10: ='Check Now 26.17 Analysis'!C13 -> 97
B11: Total Actual Testing Effort | C11: 0 | D11: 0 | E11: 0 | F11: 0 | G11: 0 | H11: 58 | I11: 73 | J11: 83 | K11: ='Check Now 26.17 Analysis'!C14 -> 99.5
B12: Bug Fixing Actual Effort | C12: 0 | D12: 0 | E12: 0 | F12: 0 | G12: 0 | H12: 0 | I12: 14 | J12: 7 | K12: ='Check Now 26.17 Analysis'!C15 -> 2
B13: Sum of Actual Hours | C13: 567.76 | D13: 599.79 | E13: 667.21 | F13: 596.76 | G13: 547.89 | H13: 757.58 | I13: 692.26 | J13: 840.18 | K13: ='Check Now 26.17 Analysis'!C16 -> 875.96
B14: Sum of Working Hours | C14: 680 | D14: 455 | E14: 517 | F14: 506 | G14: 444.5 | H14: 572 | I14: 653 | J14: 708 | K14: ='Check Now 26.17 Analysis'!C17 -> 680
B16: Kpi Indicators Per Team
B17: Team | C17: Check Now 25.9 | D17: Check Now 25.10 | E17: Check Now 25.11 | F17: Check Now 25.12 | G17: Check Now 25.13 | H17: Check Now 25.14 | I17: Check Now 26.15 | J17: Check Now 26.16 | K17: Check Now 26.17
B18: Design | C18: 0.79809966 | D18: 0.62691183 | E18: 0.74432578 | F18: 0.6152927 | G18: 0.65694498 | H18: 0.58839882 | I18: 0.82350061 | J18: 0.80396052 | K18: ='Kpi Indicators'!I17 -> 0.9387084
B19: Development | C19: 0.65546725 | D19: 0.85391469 | E19: 1.0025699 | F19: 1.0370555 | G19: 1.0492732 | H19: 0.93798984 | I19: 0.98769082 | J19: 0.99666911 | K19: ='Kpi Indicators'!I18 -> 0.97379135
B20: Front End | C20: 0.70965016 | D20: 0.8282981 | E20: 0.68234265 | F20: 0.80212597 | G20: 0.85231117 | H20: 0.79404114 | I20: 0.82176143 | J20: 0.77447956 | K20: ='Kpi Indicators'!I19 -> 0.81106269
B21: Testing | C21: NA | D21: NA | E21: NA | F21: NA | G21: NA | H21: 0.88979048 | I21: 0.97796992 | J21: 0.89605321 | K21: ='Kpi Indicators'!I20 -> 1.0009691
B23: Performance Rate Per Team | M23: Utilization Per Team
B24: Team | C24: Check Now 25.9 | D24: Check Now 25.10 | E24: Check Now 25.11 | F24: Check Now 25.12 | G24: Check Now 25.13 | H24: Check Now 25.14 | I24: Check Now 26.15 | J24: Check Now 26.16 | K24: Check Now 26.17 | M24: Team | N24: Check Now 25.9 | O24: Check Now 25.10 | P24: Check Now 25.11 | Q24: Check Now 25.12 | R24: Check Now 25.13 | S24: Check Now 25.14 | T24: Check Now 26.15 | U24: Check Now 26.16 | V24: Check Now 26.17
B25: Design | C25: 0.82937708 | D25: 0.92079104 | E25: 0.76584714 | F25: 0.76874352 | G25: 0.73557148 | H25: 0.84959705 | I25: 0.7115629 | J25: 0.74353314 | K25: ='Check Now 26.17 Full Analysis'!H6 -> 0.66122424 | M25: Design | N25: 4.7313333 | O25: 1.6275362 | P25: 1.0839773 | Q25: 0.97544 | R25: 0.89830688 | S25: 1.0917708 | T25: 0.81188034 | U25: 1.0623429 | V25: ='Check Now 26.17 Full Analysis'!I6 -> 1.5392118
B26: Development | C26: 0.82937708 | D26: 0.90295359 | E26: 0.89298893 | F26: 0.9638009 | G26: 0.90062112 | H26: 0.66520788 | I26: 0.79058824 | J26: 0.82905983 | K26: ='Check Now 26.17 Full Analysis'!H7 -> 0.70229008 | M26: Development | N26: 1.0459184 | O26: 1.2467532 | P26: 1.527027 | Q26: 1.442953 | R26: 1.6914894 | S26: 1.3187135 | T26: 1.2957317 | U26: 1.3085714 | V26: ='Check Now 26.17 Full Analysis'!I7 -> 1.3333333
B27: Front End | C27: 0.82937708 | D27: 0.79599499 | E27: 0.80965645 | F27: 0.7189441 | G27: 0.63447251 | H27: 0.78732566 | I27: 0.63950667 | J27: 0.65317905 | K27: ='Check Now 26.17 Full Analysis'!H8 -> 0.68672199 | M27: Front End | N27: 1.9377474 | O27: 1.3243243 | P27: 1.2295374 | Q27: 1.1199569 | R27: 1.1875 | S27: 1.2107213 | T27: 1.032351 | U27: 1.1884375 | V27: ='Check Now 26.17 Full Analysis'!I8 -> 0.97247706
B28: Testing | C28: NA | D28: NA | E28: NA | F28: NA | G28: NA | H28: 0.768 | I28: 0.86842105 | J28: 0.84393064 | K28: ='Check Now 26.17 Full Analysis'!H9 -> 0.91079812 | M28: Testing | N28: NA | O28: NA | P28: NA | Q28: NA | R28: NA | S28: 0.82857143 | T28: 1.0428571 | U28: 1.1857143 | V28: ='Check Now 26.17 Full Analysis'!I9 -> 1.4214286
B30: Done Tasks Per Team | M30: MidSprint_Addition Per Team
B31: Team | C31: Check Now 25.9 | D31: Check Now 25.10 | E31: Check Now 25.11 | F31: Check Now 25.12 | G31: Check Now 25.13 | H31: Check Now 25.14 | I31: Check Now 26.15 | J31: Check Now 26.16 | K31: Check Now 26.17 | M31: Team | N31: Check Now 25.9 | O31: Check Now 25.10 | P31: Check Now 25.11 | Q31: Check Now 25.12 | R31: Check Now 25.13 | S31: Check Now 25.14 | T31: Check Now 26.15 | U31: Check Now 26.16 | V31: Check Now 26.17
B32: Design | C32: 0.22727273 | D32: 0.4 | E32: 0.68965517 | F32: 0.52 | G32: 0.6 | H32: 0.44186047 | I32: 0.85714286 | J32: 0.78431373 | K32: ='Check Now 26.17 Full Analysis'!I20 -> 0.93220339 | M32: Design | N32: 0 | O32: 0.28 | P32: 0.13793103 | Q32: 0.16 | R32: 0.15 | S32: 0.20930233 | T32: 0.071428571 | U32: 0 | V32: ='Check Now 26.17 Full Analysis'!H34 -> 0.016949153
B33: Development | C33: 0.55 | D33: 0.775 | E33: 0.95918367 | F33: 1 | G33: 1 | H33: 0.96153846 | I33: 1 | J33: 1 | K33: ='Check Now 26.17 Full Analysis'!I21 -> 1 | M33: Development | N33: 0.038461538 | O33: 0.05 | P33: 0 | Q33: 0 | R33: 0 | S33: 0.038461538 | T33: 0 | U33: 0 | V33: ='Check Now 26.17 Full Analysis'!H35 -> 0
B34: Front End | C34: 0.5 | D34: 0.76666667 | E34: 0.56779661 | F34: 0.7804878 | G34: 0.86666667 | H34: 0.73643411 | I34: 0.84375 | J34: 0.75 | K34: ='Check Now 26.17 Full Analysis'!I22 -> 0.82352941 | M34: Front End | N34: 0 | O34: 0.23333333 | P34: 0.084745763 | Q34: 0.17073171 | R34: 0.093333333 | S34: 0.11627907 | T34: 0.0625 | U34: 0.10576923 | V34: ='Check Now 26.17 Full Analysis'!H36 -> 0.019607843
B35: Testing | C35: NA | D35: NA | E35: NA | F35: NA | G35: NA | H35: 0.93333333 | I35: 1 | J35: 0.86956522 | K35: ='Check Now 26.17 Full Analysis'!I23 -> 0.96666667 | M35: Testing | N35: NA | O35: NA | P35: NA | Q35: NA | R35: NA | S35: 0 | T35: 0 | U35: 0 | V35: ='Check Now 26.17 Full Analysis'!H37 -> 0
M37: Ad-hoc % Per Team
M38: Team | N38: Check Now 26.15 | O38: Check Now 26.16 | P38: Check Now 26.17
M39: Design | N39: 0 | O39: 0.078431373 | P39: ='Check Now 26.17 Full Analysis'!H48 -> 0.050847458
M40: Development | N40: 0.033333333 | O40: 0.096774194 | P40: ='Check Now 26.17 Full Analysis'!H49 -> 0.125
M41: Front End | N41: 0.083333333 | O41: 0.048076923 | P41: ='Check Now 26.17 Full Analysis'!H50 -> 0.058823529
M42: Testing | N42: 0 | O42: 0 | P42: ='Check Now 26.17 Full Analysis'!H51 -> 0

Sheet Check Now 26.17 Full Analysis
B2: Sprint Name: Check Now 26.17
B3: Date: 25 JAN to 05 FEB
B5: Row Labels | C5: Performance Rate | D5: Utilization Per Staff | G5: Team | H5: Performance Rate | I5: Utilization Per Staff
B6: Ahmed Talaat <atalaat@youxel.com> | C6: ='Check Now 26.17 Analysis'!P51 -> 0.35616438 | D6: ='Check Now 26.17 Analysis'!Q51 -> 1 | G6: Design | H6: ='Check Now 26.17 Analysis'!P88 -> 0.66122424 | I6: ='Check Now 26.17 Analysis'!Q88 -> 1.5392118
B7: Alaa Ezzat <aezzat@youxel.com> | C7: ='Check Now 26.17 Analysis'!P52 -> 0.57070707 | D7: ='Check Now 26.17 Analysis'!Q52 -> 1.4285714 | G7: Development | H7: ='Check Now 26.17 Analysis'!P89 -> 0.70229008 | I7: ='Check Now 26.17 Analysis'!Q89 -> 1.3333333
B8: Enas Diab <ediab@youxel.com> | C8: ='Check Now 26.17 Analysis'!P53 -> 0.8 | D8: ='Check Now 26.17 Analysis'!Q53 -> 0.38888889 | G8: Front End | H8: ='Check Now 26.17 Analysis'!P90 -> 0.68672199 | I8: ='Check Now 26.17 Analysis'!Q90 -> 0.97247706
B9: Galal Torkey <gtorkey@youxel.com> | C9: ='Check Now 26.17 Analysis'!P54 -> 0.91079812 | D9: ='Check Now 26.17 Analysis'!Q54 -> 1.4214286 | G9: Testing | H9: ='Check Now 26.17 Analysis'!P91 -> 0.91079812 | I9: ='Check Now 26.17 Analysis'!Q91 -> 1.4214286
B10: Hussein Abdallah <habdallah@youxel.com> | C10: ='Check Now 26.17 Analysis'!P55 -> 0.61935484 | D10: ='Check Now 26.17 Analysis'!Q55 -> 1.1 | G10: Grand Total | H10: ='Check Now 26.17 Analysis'!P92 -> 0.70741189 | I10: ='Check Now 26.17 Analysis'!Q92 -> 1.2881765
B11: Mahmoud Adel Ali <madeel@youxel.com> | C11: ='Check Now 26.17 Analysis'!P56 -> 0.90384615 | D11: ='Check Now 26.17 Analysis'!Q56 -> 1.8571429
B12: Mahmoud Ibrahim Elfeqy <mfeqy@youxel.com> | C12: ='Check Now 26.17 Analysis'!P57 -> 0.75294118 | D12: ='Check Now 26.17 Analysis'!Q57 -> 1.2142857
B13: Mariam Mohamed Saeed <msaeed@youxel.com> | C13: ='Check Now 26.17 Analysis'!P58 -> 0.52857615 | D13: ='Check Now 26.17 Analysis'!Q58 -> 1.5975714
B14: Mohamed Mustafa Farrag <mfarrag@youxel.com> | C14: ='Check Now 26.17 Analysis'!P59 -> 0.98989899 | D14: ='Check Now 26.17 Analysis'!Q59 -> 0.63265306
B15: Salma Sameh <ssameh@youxel.com> | C15: ='Check Now 26.17 Analysis'!P60 -> 0.76447346 | D15: ='Check Now 26.17 Analysis'!Q60 -> 1.5702857
B16: Shimaa Mohamed Elsayed <shhadad@youxel.com> | C16: ='Check Now 26.17 Analysis'!P61 -> 0.70400169 | D16: ='Check Now 26.17 Analysis'!Q61 -> 1.4398413
B17: Grand Total | C17: ='Check Now 26.17 Analysis'!P62 -> 0.70741189 | D17: ='Check Now 26.17 Analysis'!Q62 -> 1.2881765
B19: Row Labels | C19: Grand Total | D19: Done Tasks % | G19: Row Labels | H19: Grand Total | I19: Done Tasks %
B20: Ahmed Talaat <atalaat@youxel.com> | C20: ='Check Now 26.17 Analysis'!P95 -> 4 | D20: ='Check Now 26.17 Analysis'!Q95 -> 1 | G20: Design | H20: ='Check Now 26.17 Analysis'!P132 -> 59 | I20: ='Check Now 26.17 Analysis'!Q132 -> 0.93220339
B21: Alaa Ezzat <aezzat@youxel.com> | C21: ='Check Now 26.17 Analysis'!P96 -> 20 | D21: ='Check Now 26.17 Analysis'!Q96 -> 0.8 | G21: Development | H21: ='Check Now 26.17 Analysis'!P133 -> 32 | I21: ='Check Now 26.17 Analysis'!Q133 -> 1
B22: Enas Diab <ediab@youxel.com> | C22: ='Check Now 26.17 Analysis'!P97 -> 3 | D22: ='Check Now 26.17 Analysis'!Q97 -> 1 | G22: Front End | H22: ='Check Now 26.17 Analysis'!P134 -> 51 | I22: ='Check Now 26.17 Analysis'!Q134 -> 0.82352941
B23: Galal Torkey <gtorkey@youxel.com> | C23: ='Check Now 26.17 Analysis'!P98 -> 30 | D23: ='Check Now 26.17 Analysis'!Q98 -> 0.96666667 | G23: Testing | H23: ='Check Now 26.17 Analysis'!P135 -> 30 | I23: ='Check Now 26.17 Analysis'!Q135 -> 0.96666667
B24: Hussein Abdallah <habdallah@youxel.com> | C24: ='Check Now 26.17 Analysis'!P99 -> 14 | D24: ='Check Now 26.17 Analysis'!Q99 -> 1 | G24: Grand Total | H24: ='Check Now 26.17 Analysis'!P136 -> 172 | I24: ='Check Now 26.17 Analysis'!Q136 -> 0.91860465
B25: Mahmoud Adel Ali <madeel@youxel.com> | C25: ='Check Now 26.17 Analysis'!P100 -> 17 | D25: ='Check Now 26.17 Analysis'!Q100 -> 1
B26: Mahmoud Ibrahim Elfeqy <mfeqy@youxel.com> | C26: ='Check Now 26.17 Analysis'!P101 -> 11 | D26: ='Check Now 26.17 Analysis'!Q101 -> 1
B27: Mariam Mohamed Saeed <msaeed@youxel.com> | C27: ='Check Now 26.17 Analysis'!P102 -> 19 | D27: ='Check Now 26.17 Analysis'!Q102 -> 0.78947368
B28: Mohamed Mustafa Farrag <mfarrag@youxel.com> | C28: ='Check Now 26.17 Analysis'!P103 -> 14 | D28: ='Check Now 26.17 Analysis'!Q103 -> 0.64285714
B29: Salma Sameh <ssameh@youxel.com> | C29: ='Check Now 26.17 Analysis'!P104 -> 16 | D29: ='Check Now 26.17 Analysis'!Q104 -> 1
B30: Shimaa Mohamed Elsayed <shhadad@youxel.com> | C30: ='Check Now 26.17 Analysis'!P105 -> 24 | D30: ='Check Now 26.17 Analysis'!Q105 -> 1
B31: Grand Total | C31: ='Check Now 26.17 Analysis'!P106 -> 172 | D31: ='Check Now 26.17 Analysis'!Q106 -> 0.91860465
B33: Team member | C33: Team | D33: MidSprint_Addition % | G33: Team | H33: MidSprint_Addition %
B34: Ahmed Talaat <atalaat@youxel.com> | C34: Development | D34: ='Check Now 26.17 Analysis'!Q140 -> 0 | G34: Design | H34: ='Check Now 26.17 Analysis'!P181 -> 0.016949153
B35: Alaa Ezzat <aezzat@youxel.com> | C35: Frontend | D35: ='Check Now 26.17 Analysis'!Q141 -> 0 | G35: Development | H35: ='Check Now 26.17 Analysis'!P182 -> 0
B36: Enas Diab <ediab@youxel.com> | C36: Frontend | D36: ='Check Now 26.17 Analysis'!Q142 -> 0 | G36: Front End | H36: ='Check Now 26.17 Analysis'!P183 -> 0.019607843
B37: Galal Torkey <gtorkey@youxel.com> | C37: Testing | D37: ='Check Now 26.17 Analysis'!Q143 -> 0 | G37: Testing | H37: ='Check Now 26.17 Analysis'!P184 -> 0
B38: Hussein Abdallah <habdallah@youxel.com> | C38: Frontend | D38: ='Check Now 26.17 Analysis'!Q144 -> 0.071428571 | G38: Grand Total | H38: ='Check Now 26.17 Analysis'!P185 -> 0.011627907
B39: Mahmoud Adel Ali <madeel@youxel.com> | C39: Development | D39: ='Check Now 26.17 Analysis'!Q145 -> 0
B40: Mahmoud Ibrahim Elfeqy <mfeqy@youxel.com> | C40: Development | D40: ='Check Now 26.17 Analysis'!Q146 -> 0
B41: Mariam Mohamed Saeed <msaeed@youxel.com> | C41: Design | D41: ='Check Now 26.17 Analysis'!Q147 -> 0
B42: Mohamed Mustafa Farrag <mfarrag@youxel.com> | C42: Frontend | D42: ='Check Now 26.17 Analysis'!Q148 -> 0
B43: Salma Sameh <ssameh@youxel.com> | C43: Design | D43: ='Check Now 26.17 Analysis'!Q149 -> 0
B44: Shimaa Mohamed Elsayed <shhadad@youxel.com> | C44: Design | D44: ='Check Now 26.17 Analysis'!Q150 -> 0.041666667
...

Sheet Kpi Indicators
B2: Row Labels | C2: Performance Rate | D2: Weight | E2: Utilization Per Staff | F2: Weight | G2: Done Tasks % | H2: Weight | I2: KPI
B3: Ahmed Talaat <atalaat@youxel.com> | C3: ='Check Now 26.17 Analysis'!P51 -> 0.35616438 | D3: 0.2 | E3: ='Check Now 26.17 Analysis'!Q51 -> 1 | F3: 0.1 | G3: ='Check Now 26.17 Analysis'!Q95 -> 1 | H3: 0.7 | I3: =(C3*D3)+(E3*F3)+(G3*H3) -> 0.87123288
B4: Alaa Ezzat <aezzat@youxel.com> | C4: ='Check Now 26.17 Analysis'!P52 -> 0.57070707 | D4: 0.2 | E4: ='Check Now 26.17 Analysis'!Q52 -> 1.4285714 | F4: 0.1 | G4: ='Check Now 26.17 Analysis'!Q96 -> 0.8 | H4: 0.7 | I4: =(C4*D4)+(E4*F4)+(G4*H4) -> 0.81699856
B5: Enas Diab <ediab@youxel.com> | C5: ='Check Now 26.17 Analysis'!P53 -> 0.8 | D5: 0.2 | E5: ='Check Now 26.17 Analysis'!Q53 -> 0.38888889 | F5: 0.1 | G5: ='Check Now 26.17 Analysis'!Q97 -> 1 | H5: 0.7 | I5: =(C5*D5)+(E5*F5)+(G5*H5) -> 0.89888889
B6: Galal Torkey <gtorkey@youxel.com> | C6: ='Check Now 26.17 Analysis'!P54 -> 0.91079812 | D6: 0.2 | E6: ='Check Now 26.17 Analysis'!Q54 -> 1.4214286 | F6: 0.1 | G6: ='Check Now 26.17 Analysis'!Q98 -> 0.96666667 | H6: 0.7 | I6: =(C6*D6)+(E6*F6)+(G6*H6) -> 1.0009691
B7: Hussein Abdallah <habdallah@youxel.com> | C7: ='Check Now 26.17 Analysis'!P55 -> 0.61935484 | D7: 0.2 | E7: ='Check Now 26.17 Analysis'!Q55 -> 1.1 | F7: 0.1 | G7: ='Check Now 26.17 Analysis'!Q99 -> 1 | H7: 0.7 | I7: =(C7*D7)+(E7*F7)+(G7*H7) -> 0.93387097
B8: Mahmoud Adel Ali <madeel@youxel.com> | C8: ='Check Now 26.17 Analysis'!P56 -> 0.90384615 | D8: 0.2 | E8: ='Check Now 26.17 Analysis'!Q56 -> 1.8571429 | F8: 0.1 | G8: ='Check Now 26.17 Analysis'!Q100 -> 1 | H8: 0.7 | I8: =(C8*D8)+(E8*F8)+(G8*H8) -> 1.0664835
B9: Mahmoud Ibrahim Elfeqy <mfeqy@youxel.com> | C9: ='Check Now 26.17 Analysis'!P57 -> 0.75294118 | D9: 0.2 | E9: ='Check Now 26.17 Analysis'!Q57 -> 1.2142857 | F9: 0.1 | G9: ='Check Now 26.17 Analysis'!Q101 -> 1 | H9: 0.7 | I9: =(C9*D9)+(E9*F9)+(G9*H9) -> 0.97201681
B10: Mariam Mohamed Saeed <msaeed@youxel.com> | C10: ='Check Now 26.17 Analysis'!P58 -> 0.52857615 | D10: 0.2 | E10: ='Check Now 26.17 Analysis'!Q58 -> 1.5975714 | F10: 0.1 | G10: ='Check Now 26.17 Analysis'!Q102 -> 0.78947368 | H10: 0.7 | I10: =(C10*D10)+(E10*F10)+(G10*H10) -> 0.81810395
B11: Mohamed Mustafa Farrag <mfarrag@youxel.com> | C11: ='Check Now 26.17 Analysis'!P59 -> 0.98989899 | D11: 0.2 | E11: ='Check Now 26.17 Analysis'!Q59 -> 0.63265306 | F11: 0.1 | G11: ='Check Now 26.17 Analysis'!Q103 -> 0.64285714 | H11: 0.7 | I11: =(C11*D11)+(E11*F11)+(G11*H11) -> 0.7112451
B12: Salma Sameh <ssameh@youxel.com> | C12: ='Check Now 26.17 Analysis'!P60 -> 0.76447346 | D12: 0.2 | E12: ='Check Now 26.17 Analysis'!Q60 -> 1.5702857 | F12: 0.1 | G12: ='Check Now 26.17 Analysis'!Q104 -> 1 | H12: 0.7 | I12: =(C12*D12)+(E12*F12)+(G12*H12) -> 1.0099233
B13: Shimaa Mohamed Elsayed <shhadad@youxel.com> | C13: ='Check Now 26.17 Analysis'!P61 -> 0.70400169 | D13: 0.2 | E13: ='Check Now 26.17 Analysis'!Q61 -> 1.4398413 | F13: 0.1 | G13: ='Check Now 26.17 Analysis'!Q105 -> 1 | H13: 0.7 | I13: =(C13*D13)+(E13*F13)+(G13*H13) -> 0.98478447
B14: Grand Total | C14: ='Check Now 26.17 Analysis'!P62 -> 0.70741189 | D14: 0.2 | E14: ='Check Now 26.17 Analysis'!Q62 -> 1.2881765 | F14: 0.1 | G14: ='Check Now 26.17 Analysis'!Q106 -> 0.91860465 | H14: 0.7 | I14: =(C14*D14)+(E14*F14)+(G14*H14) -> 0.91332328
B16: Team | C16: Performance Rate | D16: Weight | E16: Utilization Per Staff | F16: Weight | G16: Done Tasks % | H16: Weight | I16: KPI
B17: Design | C17: ='Check Now 26.17 Analysis'!P88 -> 0.66122424 | D17: 0.2 | E17: ='Check Now 26.17 Analysis'!Q88 -> 1.5392118 | F17: 0.1 | G17: ='Check Now 26.17 Analysis'!Q132 -> 0.93220339 | H17: 0.7 | I17: =(C17*D17)+(E17*F17)+(G17*H17) -> 0.9387084
B18: Development | C18: ='Check Now 26.17 Analysis'!P89 -> 0.70229008 | D18: 0.2 | E18: ='Check Now 26.17 Analysis'!Q89 -> 1.3333333 | F18: 0.1 | G18: ='Check Now 26.17 Analysis'!Q133 -> 1 | H18: 0.7 | I18: =(C18*D18)+(E18*F18)+(G18*H18) -> 0.97379135
B19: Front End | C19: ='Check Now 26.17 Analysis'!P90 -> 0.68672199 | D19: 0.2 | E19: ='Check Now 26.17 Analysis'!Q90 -> 0.97247706 | F19: 0.1 | G19: ='Check Now 26.17 Analysis'!Q134 -> 0.82352941 | H19: 0.7 | I19: =(C19*D19)+(E19*F19)+(G19*H19) -> 0.81106269
B20: Testing | C20: ='Check Now 26.17 Analysis'!P91 -> 0.91079812 | D20: 0.2 | E20: ='Check Now 26.17 Analysis'!Q91 -> 1.4214286 | F20: 0.1 | G20: ='Check Now 26.17 Analysis'!Q135 -> 0.96666667 | H20: 0.7 | I20: =(C20*D20)+(E20*F20)+(G20*H20) -> 1.0009691
B21: Grand Total | C21: ='Check Now 26.17 Analysis'!P92 -> 0.70741189 | D21: 0.2 | E21: ='Check Now 26.17 Analysis'!Q92 -> 1.2881765 | F21: 0.1 | G21: ='Check Now 26.17 Analysis'!Q136 -> 0.91860465 | H21: 0.7 | I21: =(C21*D21)+(E21*F21)+(G21*H21) -> 0.91332328

Sheet Capacity
B2: CHECK NOW (Check Now 26.17)
B3: Team member | C3: Team | D3: Total Expected Working Hours per Sprint | E3: Total official vacation | F3: Total personal Days Off | G3: Remaining Capacity | I3: Team | J3: Now
B4: Ahmed Talaat <atalaat@youxel.com> | C4: Development | D4: =7*10 -> 70 | E4: 0 | F4: 1 | G4: =7*9 -> 63 | I4: Design | J4: =SUMIF(C4:C14,C13,G4:G14) -> 203
B5: Alaa Ezzat <aezzat@youxel.com> | C5: Frontend | D5: =7*10 -> 70 | E5: 0 | F5: 1 | G5: =7*9 -> 63 | I5: Development | J5: =SUMIF(C4:C14,C9,G4:G14) -> 189
B6: Enas Diab <ediab@youxel.com> | C6: Frontend | D6: =4*10 -> 40 | E6: 0 | F6: 1 | G6: =4*9 -> 36 | I6: Front End | J6: =SUMIF(C4:C14,C8,G4:G14) -> 218
B7: Galal Torkey <gtorkey@youxel.com> | C7: Testing | D7: =7*10 -> 70 | E7: 0 | F7: 0 | G7: =7*10 -> 70 | I7: Testing | J7: =SUMIF(C4:C14,C7,G4:G14) -> 70
B8: Hussein Abdallah <habdallah@youxel.com> | C8: Frontend | D8: =7*10 -> 70 | E8: 0 | F8: 0 | G8: =7*10 -> 70 | I8: IOS Dev | J8: =SUMIF(C4:C14,#REF!,G4:G14) -> 0
B9: Mahmoud Adel Ali <madeel@youxel.com> | C9: Development | D9: =7*10 -> 70 | E9: 0 | F9: 2 | G9: =7*8 -> 56 | I9: Andriod Dev | J9: =SUMIF(C4:C14,#REF!,G4:G14) -> 0
B10: Mahmoud Ibrahim Elfeqy <mfeqy@youxel.com> | C10: Development | D10: =7*10 -> 70 | E10: 0 | F10: 0 | G10: =7*10 -> 70 | I10: Total | J10: =SUM(J4:J9) -> 680
B11: Mariam Mohamed Saeed <msaeed@youxel.com> | C11: Design | D11: =7*10 -> 70 | E11: 0 | F11: 0 | G11: =7*10 -> 70
B12: Mohamed Mustafa Farrag <mfarrag@youxel.com> | C12: Frontend | D12: =7*10 -> 70 | E12: 0 | F12: 3 | G12: =7*7 -> 49
B13: Salma Sameh <ssameh@youxel.com> | C13: Design | D13: =7*10 -> 70 | E13: 0 | F13: 0 | G13: =7*10 -> 70
B14: Shimaa Mohamed Elsayed <shhadad@youxel.com> | C14: Design | D14: =7*10 -> 70 | E14: 0 | F14: 1 | G14: =7*9 -> 63
B15: Total | G15: =SUM(G4:G14) -> 680

Sheet Check Now 26.17
B2: Sprint Name: Check Now 26.17
B3: Date: 25 JAN to 05 FEB
B5: US
B6: EPIC | C6: Parent | D6: Work Item Type | E6: Title | F6: Story Points | G6: State | H6: Assigned To | I6: Original Estimate | J6: Completed Work | K6: Remaining Work | L6: Priority | M6: Severity | N6: Phase | O6: Dev delivery date | P6: QC Delivery date | Q6: Tags | R6: Task Category | S6: Activity
B7: CHECK UI Library | C7: 260293 | D7: User Story | E7: Breadcrumb Component | F7: 3 | G7: Ready for release | L7: 2 | Q7: CHECK UI Library
B8: CHECK UI Library | C8: 227974 | D8: User Story | E8: Lottie Component | F8: 3 | G8: Ready for release | L8: 2 | Q8: CHECK UI Library
B9: CHECK UI Library | C9: 228363 | D9: User Story | E9: Input Switch Component | F9: 5 | G9: Ready for release | L9: 2 | N9: Development | Q9: CHECK UI Library
B10: CHECK UI Library | C10: 228369 | D10: User Story | E10: Galleria Component | F10: 3 | G10: Ready for release | L10: 2 | Q10: CHECK UI Library
B11: CHECK UI Library | C11: 255494 | D11: User Story | E11: Table component | F11: 3 | G11: In Development | L11: 2 | Q11: CHECK UI Library
B12: CHECK UI Library | C12: 227974 | D12: User Story | E12: Design System Adjustments | F12: 5 | G12: Active | L12: 2 | Q12: CHECK UI Library
B13: Communication Module (Messages) | C13: 228964 | D13: User Story | E13: Create Chat App | F13: 8 | G13: In Development | L13: 1 | Q13: Communication Module (Messages)
B14: Communication Module (Messages) | C14: 228960 | D14: User Story | E14: As a user I can send text message in a conversation | F14: 5 | G14: In Development | L14: 1 | Q14: Communication Module (Messages)
B15: Communication Module (Messages) | C15: 228960 | D15: User Story | E15: As a user I can see list of my conversations | F15: 3 | G15: In Development | L15: 1 | Q15: Communication Module (Messages)
B16: Communication Module (Messages) | C16: 228960 | D16: User Story | E16: As a user I can start new conversation | F16: 3 | G16: Ready For Testing | L16: 1 | Q16: Communication Module (Messages)
B17: Communication Module (Messages) | C17: 228960 | D17: User Story | E17: As a user I can reply on any message | F17: 5 | G17: Ready For Review | L17: 2 | Q17: Communication Module (Messages)
B18: Communication Module (Messages) | C18: 228960 | D18: User Story | E18: As a user I can delete my messages | F18: 3 | G18: Done Development | L18: 1 | Q18: Communication Module (Messages)
B19: Communication Module (Messages) | C19: 228960 | D19: User Story | E19: As a user I can mark message as unread | F19: 5 | G19: Ready For Testing | L19: 2 | Q19: Communication Module (Messages)
B20: Communication Module (Messages) | C20: 228960 | D20: User Story | E20: As a user I can send attachment in a conversation | F20: 5 | G20: In Development | L20: 2 | Q20: Communication Module (Messages)
B21: Communication Module (Messages) | C21: 228960 | D21: User Story | E21: As a user I can forward a message | F21: 5 | G21: In Development | L21: 2 | Q21: Communication Module (Messages)
... B28: Administration Module | C28: 241399 | D28: User Story | E28: Administration Portal API | F28: 5 | G28: In Development | L28: 2 | Q28: Administration Module
B29: Administration Module | C29: 241399 | D29: User Story | E29: Locations Flat Relations | F29: 3 | G29: Done Development | L29: 2
B30: Administration Module | C30: 195967 | D30: User Story | E30: Set/Edit Company information | F30: 3 | G30: Ready For Testing | L30: 1 | Q30: Administration Module
B31: Administration Module | C31: 195967 | D31: User Story | E31: Multitenancy | F31: 8 | G31: Done Development | L31: 2 | Q31: Administration Module
B32: Administration Module | C32: 195967 | D32: User Story | E32: Upload/Change Company Logo | F32: 3 | G32: Ready For Testing | L32: 1 | Q32: Administration Module
B33: Administration Module | C33: 195967 | D33: User Story | E33: Set Company Identity | F33: 5 | G33: Ready For Testing | L33: 1 | Q33: Administration Module
B34: Administration Module | C34: 195967 | D34: User Story | E34: Set / Edit the supported langauges | F34: 5 | G34: Ready For Testing | L34: 1 | Q34: Administration Module
B35: Administration Module | C35: 195968 | D35: User Story | E35: User should be able to view POI categories | F35: 3 | G35: Ready For Testing | L35: 1 | Q35: Administration Module
B36: Administration Module | C36: 195968 | D36: User Story | E36: User should be able to manage location subcategory | F36: 5 | G36: Ready For Testing | L36: 2 | Q36: Administration Module
B37: Administration Module | C37: 195968 | D37: User Story | E37: User should be able to manage Location categories | F37: 5 | G37: Ready For Testing | L37: 2 | Q37: Administration Module
B38: Administration Module | C38: 195968 | D38: User Story | E38: User should be able to manage location importance | F38: 5 | G38: Ready For Testing | L38: 2 | Q38: Administration Module
B39: Administration Module | C39: 195968 | D39: User Story | E39: User should be able to manage location account | F39: 5 | G39: Ready For Testing | L39: 2 | Q39: Administration Module
B40: Administration Module | C40: 195968 | D40: User Story | E40: User should be able to view location tree (org chart) | F40: 8 | G40: Ready For Testing | L40: 1 | Q40: Administration Module
B41: Administration Module | C41: 195968 | D41: User Story | E41: User should be able to add location optional information | F41: 5 | G41: Ready For Review | L41: 1 | Q41: Administration Module
... B50: Administration Module | C50: 195969 | D50: User Story | E50: Manage KPI Indicators (CRUD + Localization) | F50: 5 | G50: In Development | L50: 2 | Q50: Administration Module
B51: Administration Module | C51: 195969 | D51: User Story | E51: Kpi Definistion Form | F51: 5 | G51: Ready For Review | L51: 2 | N51: Development | Q51: Administration Module
B52: Administration Module | C52: 195969 | D52: User Story | E52: Kpi Definisions View | F52: 5 | G52: Ready For Testing | L52: 2 | Q52: Administration Module
B53: Workflow Library | C53: 193289 | D53: User Story | E53: Create Workflow System | F53: 5 | G53: In Development | L53: 2 | Q53: Workflow Library
B54: Learning, Development, and Process Improvement | C54: 240010 | D54: User Story | E54: Automation Testing Cycle | F54: 0 | G54: Active | L54: 2 | N54: Testing
B55: Learning, Development, and Process Improvement | C55: 260486 | D55: User Story | E55: CMMI Reports | F55: 0 | G55: Released | L55: 2 | Q55: CMMI
B56: Meetings & Support | C56: 247821 | D56: User Story | E56: Meeting logs iteration 26.17 | F56: 0 | G56: Released | L56: 2
...

Sheet Check Now 26.17 Analysis
B2: Sprint Name: Check Now 26.17
B3: Date: 25 JAN to 05 FEB
B5: Item | C5: Check Now 26.17
B6: Escaped Bugs | C6: 0
B7: MidSprint_Addition | C7: =D151 -> 2
B8: Ad-hoc | C8: =D201 -> 10
B9: Planned SP | C9: 57
B10: Actual SP | C10: 102
B11: Estimated Development Effort | C11: 569
B12: Total Actual Development Effort | C12: 776.46
B13: Estimated Testing Effort | C13: 97
B14: Total Actual Testing Effort | C14: 99.5
B15: Bug Fixing Actual Effort | C15: 2
B16: Sum of Actual Hours | C16: =D48 -> 875.96
B17: Sum of Working Hours | C17: =Capacity!G15 -> 680
B19: Measure | C19: Description | D19: Calculation | E19: Frequency | F19: Analysis
B20: Completion rate | C20: Measures the difference between the actual done story points VS. the Planned story points | D20: Actual SP / Planned SP | E20: Sprint | F20: +90%
B21: Effort estimation accuracy percentage | C21: Total Planned Development hours / Total Actual Development Hours | D21: Sum Total Planned hours/Total Actual Dev. Effort) | E21: Sprint | F21: 90% - till 120%
B22: Project Rework Rate | C22: Project Calculate man hours used in fixing the bugs returned from testing compared to the total actual dev. hours. | D22: Bug Fixing Actual Effort /Total Actual Dev. Effort) *100 | E22: Sprint | F22: 0% – 10%
B23: Escaped Bugs | C23: defects that bypass one or more testing or quality assurance stages and are later post released | D23: Number of bypass one or more testing or quality assurance stages | E23: Sprint / release | F23: 2% -15%
B24: Utilization | C24: This measure is related to the Actual effort VS. working hours | D24: (Sum of Actual hours / Sum working hours) *100 | E24: Sprint | F24: (90%-100%
B25: Effort Variance | C25: Calculate the variance of the estimated dev. Hours compared to the total actual dev. hours. | D25: ((Total Actual Dev. Effort - Estimated Dev. Effort)/ Estimated Dev. Effort )*100 | E25: Sprint | F25: 5 – 10%
B27: Measure | C27: Description | D27: Formula | E27: Value | F27: Target Range | G27: Status
B28: Completion Rate | C28: Measures the difference between the actual done story points vs. the planned story points | D28: 102 / 57 | E28: 1.7895 | F28: ≥ 90% | G28: ⚠️ Over-commitment
B29: Effort Estimation Accuracy % (Dev) | C29: Planned development hours vs. actual development hours | D29: 569 / 776 | E29: 0.7332 | F29: 90% – 120% | G29: ❌ Under-estimated
B30: Project Rework Rate | C30: Bug fixing effort compared to total actual development effort | D30: (2 / 776) × 100 | E30: 0.0026 | F30: 0% – 10% | G30: ✅ Healthy
B31: Escaped Bugs | C31: Defects found after release | D31: Count = 0 | E31: 0 bugs | F31: 2% – 15% | G31: ⚠️ Below Expected*
B32: Utilization | C32: Actual effort vs. available working hours | D32: (876 / 680) × 100 | E32: 1.2882 | F32: 90% – 100% | G32: ❌ Over-utilized
B33: Effort Variance (Dev) | C33: Variance between estimated and actual development effort | D33: ((776 − 569) / 569) × 100 | E33: 0.364 | F33: 5% – 10% | G33: ❌ High Variance
B36: Row Labels | C36: Sum of Original Estimate | D36: Sum of Completed Work | E36: Sum of Remaining Work
B37: Ahmed Talaat <atalaat@youxel.com> | C37: 26 | D37: 63 | E37: 10
B38: Alaa Ezzat <aezzat@youxel.com> | C38: 56.5 | D38: 90 | E38: 9
B39: Enas Diab <ediab@youxel.com> | C39: 12 | D39: 14 | E39: 1
B40: Galal Torkey <gtorkey@youxel.com> | C40: 97 | D40: 99.5 | E40: 7
B41: Hussein Abdallah <habdallah@youxel.com> | C41: 48 | D41: 77 | E41: 0.5
B42: Mahmoud Adel Ali <madeel@youxel.com> | C42: 94 | D42: 104 | E42: 0
B43: Mahmoud Ibrahim Elfeqy <mfeqy@youxel.com> | C43: 64 | D43: 85 | E43: 0
B44: Mariam Mohamed Saeed <msaeed@youxel.com> | C44: 64 | D44: 111.83 | E44: 9.25
B45: Mohamed Mustafa Farrag <mfarrag@youxel.com> | C45: 49 | D45: 31 | E45: 18.5
B46: Salma Sameh <ssameh@youxel.com> | C46: 89 | D46: 109.92 | E46: 6.5
...

Sheet CMMI Template
B2: Measure | C2: Description | D2: Calculation | E2: Frequency | F2: Target Range | G2: Check Now 25.9 | H2: Check Now 25.10 | I2: Check Now 25.11 | J2: Check Now 25.12 | K2: Check Now 25.13 | L2: Check Now 25.14 | M2: Check Now 26.15 | N2: Check Now 26.16 | O2: Check Now 26.17
B3: Completion rate | C3: Measures the difference between the actual done story points VS. the Planned story points | D3: Actual SP / Planned SP | E3: Sprint | F3: +90% | G3: 0.356 | H3: 0.3196 | I3: 0.5841 | J3: 0.5806 | K3: 0.5493 | L3: 0.2984 | M3: 1.1233 | N3: 0.7213 | O3: 1.7895
B4: Effort estimation accuracy percentage | C4: Total Planned Development hours / Total Actual Development Hours | D4: Sum Total Planned hours/Total Actual Dev. Effort) | E4: Sprint | F4: 90% - till 120% | G4: 1.285 | H4: 1.1933 | I4: 1.1634 | J4: 0.9682 | K4: 0.7974 | L4: 0.9929 | M4: 0.769 | N4: 0.8453 | O4: 0.7332
B5: Project Rework Rate | C5: Project Calculate man hours used in fixing the bugs returned from testing compared to the total actual dev. hours. | D5: Bug Fixing Actual Effort /Total Actual Dev. Effort) *100 | E5: Sprint | F5: 0% – 10% | G5: 0 | H5: 0 | I5: 0 | J5: 0 | K5: 0 | L5: 0 | M5: 0.0226 | N5: 0.0092 | O5: 0.0026
B6: Escaped Bugs | C6: defects that bypass one or more testing or quality assurance stages and are later post released | D6: Number of bypass one or more testing or quality assurance stages | E6: Sprint / release | F6: 2% -15% | G6: 0 bugs | H6: 0 bugs | I6: 0 bugs | J6: 0 bugs | K6: 0 bugs | L6: 0 bugs | M6: 0 bugs | N6: 0 bugs | O6: 0 bugs
B7: utilization | C7: This measure is related to the Actual effort VS. working hours | D7: (Sum of Actual hours / Sum working hours) *100 | E7: Sprint | F7: (90%-100% | G7: 0.835 | H7: 1.3187 | I7: 1.2899 | J7: 1.1803 | K7: 1.2315 | L7: 1.3252 | M7: 1.0593 | N7: 1.1864 | O7: 1.2882
B8: Dev. Effort Variance | C8: Calculate the variance of the estimated dev. Hours compared to the total actual dev. hours. | D8: ((Total Actual Dev. Effort - Estimated Dev. Effort)/ Estimated Dev. Effort )*100 | E8: Sprint | F8: 5 – 10% | G8: −22.2% | H8: −16.20% | I8: −14.05% | J8: 0.0328 | K8: 0.254 | L8: 0.0072 | M8: 0.3004 | N8: 0.1828 | O8: 0.364

Sheet  CMMI Productivity
B2: Sprint Name: Check Now 26.17
B3: Date: 25 JAN to 05 FEB
B5: CMMI Productivity
B6: Team member | C6: Team | D6: Total Expected Working Hours per Sprint | E6: Total official vacation | F6: Total personal Days Off | G6: Remaining Capacity | H6: Total orignal estimation | I6: Total working hours | J6: Actual productivity | K6: Productivity Index
B7: Ahmed Talaat <atalaat@youxel.com> | C7: Development | D7: ='Check Now 26.17 Analysis'!D239 -> 70 | E7: ='Check Now 26.17 Analysis'!E239 -> 0 | F7: ='Check Now 26.17 Analysis'!F239 -> 1 | G7: ='Check Now 26.17 Analysis'!G239 -> 63 | H7: ='Check Now 26.17 Analysis'!H239 -> 26 | I7: ='Check Now 26.17 Analysis'!I239 -> 63 | J7: =I7/G7 -> 1 | K7: =I7/H7 -> 2.4230769
B8: Alaa Ezzat <aezzat@youxel.com> | C8: Frontend | D8: ='Check Now 26.17 Analysis'!D240 -> 70 | E8: ='Check Now 26.17 Analysis'!E240 -> 0 | F8: ='Check Now 26.17 Analysis'!F240 -> 1 | G8: ='Check Now 26.17 Analysis'!G240 -> 63 | H8: ='Check Now 26.17 Analysis'!H240 -> 56.5 | I8: ='Check Now 26.17 Analysis'!I240 -> 90 | J8: =I8/G8 -> 1.4285714 | K8: =I8/H8 -> 1.5929204
B9: Enas Diab <ediab@youxel.com> | C9: Frontend | D9: ='Check Now 26.17 Analysis'!D241 -> 40 | E9: ='Check Now 26.17 Analysis'!E241 -> 0 | F9: ='Check Now 26.17 Analysis'!F241 -> 1 | G9: ='Check Now 26.17 Analysis'!G241 -> 36 | H9: ='Check Now 26.17 Analysis'!H241 -> 12 | I9: ='Check Now 26.17 Analysis'!I241 -> 14 | J9: =I9/G9 -> 0.38888889 | K9: =I9/H9 -> 1.1666667
B10: Galal Torkey <gtorkey@youxel.com> | C10: Testing | D10: ='Check Now 26.17 Analysis'!D242 -> 70 | E10: ='Check Now 26.17 Analysis'!E242 -> 0 | F10: ='Check Now 26.17 Analysis'!F242 -> 0 | G10: ='Check Now 26.17 Analysis'!G242 -> 70 | H10: ='Check Now 26.17 Analysis'!H242 -> 97 | I10: ='Check Now 26.17 Analysis'!I242 -> 99.5 | J10: =I10/G10 -> 1.4214286 | K10: =I10/H10 -> 1.0257732
B11: Hussein Abdallah <habdallah@youxel.com> | C11: Frontend | D11: ='Check Now 26.17 Analysis'!D243 -> 70 | E11: ='Check Now 26.17 Analysis'!E243 -> 0 | F11: ='Check Now 26.17 Analysis'!F243 -> 0 | G11: ='Check Now 26.17 Analysis'!G243 -> 70 | H11: ='Check Now 26.17 Analysis'!H243 -> 48 | I11: ='Check Now 26.17 Analysis'!I243 -> 77 | J11: =I11/G11 -> 1.1 | K11: =I11/H11 -> 1.6041667
B12: Mahmoud Adel Ali <madeel@youxel.com> | C12: Development | D12: ='Check Now 26.17 Analysis'!D244 -> 70 | E12: ='Check Now 26.17 Analysis'!E244 -> 0 | F12: ='Check Now 26.17 Analysis'!F244 -> 2 | G12: ='Check Now 26.17 Analysis'!G244 -> 56 | H12: ='Check Now 26.17 Analysis'!H244 -> 94 | I12: ='Check Now 26.17 Analysis'!I244 -> 104 | J12: =I12/G12 -> 1.8571429 | K12: =I12/H12 -> 1.106383
